<?xml version="1.0"?>
<robot name="hammerhead" xmlns:xacro="http://www.ros.org/wiki/xacro">

    <xacro:property name="base_width" value="0.091"/>
    <xacro:property name="base_length" value="0.195"/>
    <xacro:property name="base_height" value="0.001"/>

    <xacro:property name="wheel_radius" value="0.0325"/>
    <xacro:property name="wheel_width" value="0.025"/>
    <xacro:property name="wheel_ygap" value="0.0225"/>
    <xacro:property name="wheel_zoff" value="0.0125"/>
    <xacro:property name="wheel_xoff" value="0.075"/>

    <!-- Robot Base -->
    <link name="base_link">
        <visual>
            <geometry>
                <box size="${base_length} ${base_width} ${base_height}"/>
            </geometry>
            <material name="Cyan">
                <color rgba="0 1.0 1.0 1.0"/>
            </material>
        </visual>
    </link> 

    <!-- Robot Footprint -->
    <link name="base_footprint"/>

    <joint name="base_joint" type="fixed">
        <parent link="base_link"/>
        <child link="base_footprint"/>
        <origin xyz="0.0 0.0 ${-(wheel_radius+wheel_zoff)}" rpy="0 0 0"/>
    </joint>

    <!-- Wheels -->
    <xacro:macro name="wheel" params="prefix x_reflect y_reflect">
    <link name="${prefix}_link">
        <visual>
            <origin xyz="0 0 0" rpy="${pi/2} 0 0"/>
                <geometry>
                    <cylinder radius="${wheel_radius}" length="${wheel_width}"/>
                </geometry>
                <material name="Gray">
                    <color rgba="0.5 0.5 0.5 1.0"/>
                </material>
        </visual>
    </link>

    <joint name="${prefix}_joint" type="continuous">
        <parent link="base_link"/>
        <child link="${prefix}_link"/>
        <origin xyz="${x_reflect*wheel_xoff} ${y_reflect*(base_width/2+wheel_ygap)} ${-wheel_zoff}" rpy="0 0 0"/>
        <axis xyz="0 1 0"/>
    </joint>
    </xacro:macro>

    <xacro:wheel prefix="drivewhl_bl" x_reflect="-1" y_reflect="1" />
    <xacro:wheel prefix="drivewhl_br" x_reflect="-1" y_reflect="-1" />
    
    <xacro:wheel prefix="drivewhl_fl" x_reflect="1" y_reflect="1" />
    <xacro:wheel prefix="drivewhl_fr" x_reflect="1" y_reflect="-1" />

   <!-- Rear Platform-->
    <link name="rear_platform">
        <visual>
        <geometry>
            <box size="0.129 0.080 0.070"/>
        </geometry>
        <material name="Cyan">
            <color rgba="0 1.0 1.0 1.0"/>
        </material>
        </visual>
    </link>

    <joint name="rear_plat_joint" type="fixed">
        <parent link="base_link"/>
        <child link="rear_platform"/>
        <origin xyz="0.069 0 0.035"/>
    </joint>

    
    <!-- LIDAR -->
    <link name="lidar_base">
        <visual>
        <geometry>
            <cylinder radius="0.0325" length="0.039"/>
        </geometry>
        <material name="Black">
            <color rgba="0 0 0 1.0"/>
        </material>
        </visual>
    </link>

    <link name="lidar">
        <visual>
        <geometry>
            <cylinder radius="0.0325" length="0.0105"/>
        </geometry>
        <material name="Red">
            <color rgba="1.0 0 0 1.0"/>
        </material>
        </visual>
    </link>

    <joint name="lidar_base_joint" type="fixed">
        <parent link="rear_platform"/>
        <child link="lidar_base"/>
        <origin xyz="0.030 0 0.0545"/>
    </joint>

    <joint name="lidar_joint" type="continuous">
        <parent link="lidar_base"/>
        <child link="lidar"/>
        <origin xyz="0 0 .0195"/>
        <axis xyz="0 0 1"/>
    </joint>

    <!-- Kinect -->

</robot>